Traceback (most recent call last):
  File "C:\Users\Antho\temp.py", line 21, in scrape_attractions
    attractions_data.raise_for_status()
  File "C:\Users\Antho\AppData\Local\Programs\Python\Python311\Lib\site-packages\requests\models.py", line 1021, in raise_for_status
    raise HTTPError(http_error_msg, response=self)
requests.exceptions.HTTPError: 403 Client Error: Forbidden for url: https://realwebsite.com/attractions/New%20York%20City

During handling of the above exception, another exception occurred:

Traceback (most recent call last):
  File "C:\Users\Antho\temp.py", line 79, in <module>
    travel_guide.run()
  File "C:\Users\Antho\temp.py", line 70, in run
    self.gather_data()
  File "C:\Users\Antho\temp.py", line 12, in gather_data
    self.scrape_attractions()
  File "C:\Users\Antho\temp.py", line 25, in scrape_attractions
    raise CustomException(f"Error scraping attractions: {str(e)}")
          ^^^^^^^^^^^^^^^
NameError: name 'CustomException' is not defined. Did you mean: 'BaseException'?
